<robot
  name="gcr5g_description">
  <link
    name="base_link">
    <inertial>
      <origin
        xyz="0.000635038987172991 0.00052842091907003 0.0145511209757988"
        rpy="0 0 0" />
      <mass
        value="0.235469441856734" />
      <inertia
        ixx="0.000394110583521865"
        ixy="5.7514077247959E-06"
        ixz="1.60882204474908E-06"
        iyy="0.000393537993397388"
        iyz="1.54559410876959E-06"
        izz="0.000750439148761956" />
    </inertial>
    <visual>
      <origin
        xyz="0 0 0"
        rpy="0 0 0" />
      <geometry>
        <mesh
          filename="package://gcr5g_description/meshes/base_link.STL" />
      </geometry>
      <material
        name="">
        <color
          rgba="0.752941176470588 0.752941176470588 0.752941176470588 1" />
      </material>
    </visual>
    <collision>
      <origin
        xyz="0 0 0"
        rpy="0 0 0" />
      <geometry>
        <mesh
          filename="package://gcr5g_description/meshes/base_link.STL" />
      </geometry>
    </collision>
  </link>
  <link
    name="Link1">
    <inertial>
      <origin
        xyz="-2.29833441372716E-05 0.00939807572647894 -0.0223184970920699"
        rpy="0 0 0" />
      <mass
        value="0.287809595237489" />
      <inertia
        ixx="0.00071606792500991"
        ixy="1.00641855398766E-08"
        ixz="9.18285135267826E-08"
        iyy="0.000722346959753427"
        iyz="-8.34715505244834E-05"
        izz="0.000757341762974166" />
    </inertial>
    <visual>
      <origin
        xyz="0 0 0"
        rpy="0 0 0" />
      <geometry>
        <mesh
          filename="package://gcr5g_description/meshes/Link1.STL" />
      </geometry>
      <material
        name="">
        <color
          rgba="0.752941176470588 0.752941176470588 0.752941176470588 1" />
      </material>
    </visual>
    <collision>
      <origin
        xyz="0 0 0"
        rpy="0 0 0" />
      <geometry>
        <mesh
          filename="package://gcr5g_description/meshes/Link1.STL" />
      </geometry>
    </collision>
  </link>
  <joint
    name="Joint1"
    type="revolute">
    <origin
      xyz="0 0 0.10844"
      rpy="0 0 0" />
    <parent
      link="base_link" />
    <child
      link="Link1" />
    <axis
      xyz="0 0 1" />
    <limit
      lower="-3"
      upper="3"
      effort="1"
      velocity="1" />
  </joint>
  <link
    name="Link2">
    <inertial>
      <origin
        xyz="0.212537552875923 -0.01470428645145 1.98361437159233E-06"
        rpy="0 0 0" />
      <mass
        value="0.873895143425123" />
      <inertia
        ixx="0.00205601287417751"
        ixy="1.8943379594929E-07"
        ixz="-2.67099592179899E-06"
        iyy="0.0291535555543656"
        iyz="4.7328418872632E-07"
        izz="0.0291693793399745" />
    </inertial>
    <visual>
      <origin
        xyz="0 0 0"
        rpy="0 0 0" />
      <geometry>
        <mesh
          filename="package://gcr5g_description/meshes/Link2.STL" />
      </geometry>
      <material
        name="">
        <color
          rgba="0.752941176470588 0.752941176470588 0.752941176470588 1" />
      </material>
    </visual>
    <collision>
      <origin
        xyz="0 0 0"
        rpy="0 0 0" />
      <geometry>
        <mesh
          filename="package://gcr5g_description/meshes/Link2.STL" />
      </geometry>
    </collision>
  </link>
  <joint
    name="Joint2"
    type="revolute">
    <origin
      xyz="0 0.1348 0"
      rpy="0 0 0" />
    <parent
      link="Link1" />
    <child
      link="Link2" />
    <axis
      xyz="0 1 0" />
    <limit
      lower="-3.5"
      upper="0.5"
      effort="0"
      velocity="0" />
  </joint>
  <link
    name="Link3">
    <inertial>
      <origin
        xyz="0.161898898549927 -0.111669374007534 -4.78702954956334E-06"
        rpy="0 0 0" />
      <mass
        value="0.63535804916724" />
      <inertia
        ixx="0.000830792154033419"
        ixy="0.000174258514667893"
        ixz="3.2010453240521E-08"
        iyy="0.0165536506287756"
        iyz="1.89430598344166E-07"
        izz="0.0164555364531943" />
    </inertial>
    <visual>
      <origin
        xyz="0 0 0"
        rpy="0 0 0" />
      <geometry>
        <mesh
          filename="package://gcr5g_description/meshes/Link3.STL" />
      </geometry>
      <material
        name="">
        <color
          rgba="0.752941176470588 0.752941176470588 0.752941176470588 1" />
      </material>
    </visual>
    <collision>
      <origin
        xyz="0 0 0"
        rpy="0 0 0" />
      <geometry>
        <mesh
          filename="package://gcr5g_description/meshes/Link3.STL" />
      </geometry>
    </collision>
  </link>
  <joint
    name="Joint3"
    type="revolute">
    <origin
      xyz="0.4251 0 0"
      rpy="0 0 0" />
    <parent
      link="Link2" />
    <child
      link="Link3" />
    <axis
      xyz="0 1 0" />
    <limit
      lower="-3"
      upper="3"
      effort="1"
      velocity="1" />
  </joint>
  <link
    name="Link4">
    <inertial>
      <origin
        xyz="3.79998164479201E-06 0.0669441816664544 -0.0138821420778474"
        rpy="0 0 0" />
      <mass
        value="0.120753251857373" />
      <inertia
        ixx="0.000143656697936511"
        ixy="-3.38738120860365E-07"
        ixz="1.05158778757901E-08"
        iyy="0.000141455509049759"
        iyz="1.28676293739486E-05"
        izz="0.000134599166244764" />
    </inertial>
    <visual>
      <origin
        xyz="0 0 0"
        rpy="0 0 0" />
      <geometry>
        <mesh
          filename="package://gcr5g_description/meshes/Link4.STL" />
      </geometry>
      <material
        name="">
        <color
          rgba="0.752941176470588 0.752941176470588 0.752941176470588 1" />
      </material>
    </visual>
    <collision>
      <origin
        xyz="0 0 0"
        rpy="0 0 0" />
      <geometry>
        <mesh
          filename="package://gcr5g_description/meshes/Link4.STL" />
      </geometry>
    </collision>
  </link>
  <joint
    name="Joint4"
    type="revolute">
    <origin
      xyz="0.3919 -0.09865 0"
      rpy="0 0 0" />
    <parent
      link="Link3" />
    <child
      link="Link4" />
    <axis
      xyz="0 1 0" />
    <limit
      lower="-3.5"
      upper="0.5"
      effort="1"
      velocity="1" />
  </joint>
  <link
    name="Link5">
    <inertial>
      <origin
        xyz="-3.79997911126306E-06 0.0138821420824871 -0.0669441816786919"
        rpy="0 0 0" />
      <mass
        value="0.120753251793781" />
      <inertia
        ixx="0.000143656697905757"
        ixy="1.05158805956512E-08"
        ixz="-3.38738128716387E-07"
        iyy="0.00013459916620674"
        iyz="1.28676293614767E-05"
        izz="0.000141455509055265" />
    </inertial>
    <visual>
      <origin
        xyz="0 0 0"
        rpy="0 0 0" />
      <geometry>
        <mesh
          filename="package://gcr5g_description/meshes/Link5.STL" />
      </geometry>
      <material
        name="">
        <color
          rgba="0.752941176470588 0.752941176470588 0.752941176470588 1" />
      </material>
    </visual>
    <collision>
      <origin
        xyz="0 0 0"
        rpy="0 0 0" />
      <geometry>
        <mesh
          filename="package://gcr5g_description/meshes/Link5.STL" />
      </geometry>
    </collision>
  </link>
  <joint
    name="Joint5"
    type="revolute">
    <origin
      xyz="0 0.0735 -0.02085"
      rpy="0 0 0" />
    <parent
      link="Link4" />
    <child
      link="Link5" />
    <axis
      xyz="0 0 -1" />
    <limit
      lower="-3"
      upper="3"
      effort="1"
      velocity="1" />
  </joint>
  <link
    name="Link6">
    <inertial>
      <origin
        xyz="1.70650246711368E-07 0.0539301921218914 -0.000380624684435211"
        rpy="0 0 0" />
      <mass
        value="0.0609840111314345" />
      <inertia
        ixx="3.68176978978095E-05"
        ixy="-1.13212456335131E-12"
        ixz="-3.27208649021208E-11"
        iyy="5.71665840541626E-05"
        iyz="-2.34259828291095E-07"
        izz="3.63883679831058E-05" />
    </inertial>
    <visual>
      <origin
        xyz="0 0 0"
        rpy="0 0 0" />
      <geometry>
        <mesh
          filename="package://gcr5g_description/meshes/Link6.STL" />
      </geometry>
      <material
        name="">
        <color
          rgba="0.752941176470588 0.752941176470588 0.752941176470588 1" />
      </material>
    </visual>
    <collision>
      <origin
        xyz="0 0 0"
        rpy="0 0 0" />
      <geometry>
        <mesh
          filename="package://gcr5g_description/meshes/Link6.STL" />
      </geometry>
    </collision>
  </link>
  <joint
    name="Joint6"
    type="revolute">
    <origin
      xyz="0 0.02085 -0.0735"
      rpy="0 0 0" />
    <parent
      link="Link5" />
    <child
      link="Link6" />
    <axis
      xyz="0 1 0" />
    <limit
      lower="-3"
      upper="3"
      effort="1"
      velocity="1" />
  </joint>
  <link
    name="Link_gripper">
    <inertial>
      <origin
        xyz="-0.000793568003006229 0.14615552151135 1.76001653658421E-05"
        rpy="0 0 0" />
      <mass
        value="0.149482836163735" />
      <inertia
        ixx="0.000311880808431645"
        ixy="4.14828346027179E-07"
        ixz="4.90573612438096E-07"
        iyy="8.76595177207867E-05"
        iyz="1.3425253335016E-07"
        izz="0.000341383122308987" />
    </inertial>
    <visual>
      <origin
        xyz="0 0 0"
        rpy="0 0 0" />
      <geometry>
        <mesh
          filename="package://gcr5g_description/meshes/Link_gripper.STL" />
      </geometry>
      <material
        name="">
        <color
          rgba="0.752941176470588 0.752941176470588 0.752941176470588 1" />
      </material>
    </visual>
    <collision>
      <origin
        xyz="0 0 0"
        rpy="0 0 0" />
      <geometry>
        <mesh
          filename="package://gcr5g_description/meshes/Link_gripper.STL" />
      </geometry>
    </collision>
  </link>
  <joint
    name="Joint_gripper"
    type="fixed">
    <origin
      xyz="0 0 0"
      rpy="0 0 0" />
    <parent
      link="Link6" />
    <child
      link="Link_gripper" />
    <axis
      xyz="0 0 0" />
  </joint>
  <link
    name="Link_gripper1">
    <inertial>
      <origin
        xyz="0.00501458682842326 0.0129905416241217 0.00830000223116439"
        rpy="0 0 0" />
      <mass
        value="0.00770136927180468" />
      <inertia
        ixx="2.70199630479076E-06"
        ixy="-9.22317780806694E-07"
        ixz="7.32574042723678E-13"
        iyy="8.80119957709075E-07"
        iyz="-5.01751864570229E-13"
        izz="2.8787832581864E-06" />
    </inertial>
    <visual>
      <origin
        xyz="0 0 0"
        rpy="0 0 0" />
      <geometry>
        <mesh
          filename="package://gcr5g_description/meshes/Link_gripper1.STL" />
      </geometry>
      <material
        name="">
        <color
          rgba="0.752941176470588 0.752941176470588 0.752941176470588 1" />
      </material>
    </visual>
    <collision>
      <origin
        xyz="0 0 0"
        rpy="0 0 0" />
      <geometry>
        <mesh
          filename="package://gcr5g_description/meshes/Link_gripper1.STL" />
      </geometry>
    </collision>
  </link>
  <joint
    name="Joint_gripper1"
    type="revolute">
    <origin
      xyz="0.0163 0.19555 -0.0083"
      rpy="0 0 0" />
    <parent
      link="Link_gripper" />
    <child
      link="Link_gripper1" />
    <axis
      xyz="0 0 1" />
    <limit
      lower="-0.35"
      upper="0.35"
      effort="1"
      velocity="1" />
  </joint>
  <link
    name="Link_gripper1_1">
    <inertial>
      <origin
        xyz="-0.022488743514532 -0.0081742813367448 0.0098852244611465"
        rpy="0 0 0" />
      <mass
        value="0.00588778350213335" />
      <inertia
        ixx="2.50492828022574E-07"
        ixy="-3.70699284902475E-07"
        ixz="1.55513399716011E-08"
        iyy="1.50021376058038E-06"
        iyz="4.14114994655371E-09"
        izz="1.55745563663569E-06" />
    </inertial>
    <visual>
      <origin
        xyz="0 0 0"
        rpy="0 0 0" />
      <geometry>
        <mesh
          filename="package://gcr5g_description/meshes/Link_gripper1_1.STL" />
      </geometry>
      <material
        name="">
        <color
          rgba="0.752941176470588 0.752941176470588 0.752941176470588 1" />
      </material>
    </visual>
    <collision>
      <origin
        xyz="0 0 0"
        rpy="0 0 0" />
      <geometry>
        <mesh
          filename="package://gcr5g_description/meshes/Link_gripper1_1.STL" />
      </geometry>
    </collision>
  </link>
  <joint
    name="Joint_gripper1_1"
    type="revolute">
    <origin
      xyz="0.01893 0.05164 -0.0017"
      rpy="0 0 -1.5708" />
    <parent
      link="Link_gripper1" />
    <child
      link="Link_gripper1_1" />
    <axis
      xyz="0 0 1" />
    <limit
      lower="-0.35"
      upper="0.35"
      effort="1"
      velocity="1" />
		<mimic
			joint ="Joint_gripper1"
			multiplier="-1"
			offset="0"/>
  </joint>
  <link
    name="Link_gripper2">
    <inertial>
      <origin
        xyz="-0.0206769022168571 0.00759969192184873 0.00808102054231884"
        rpy="0 0 0" />
      <mass
        value="0.0039532133064862" />
      <inertia
        ixx="3.83200073413275E-07"
        ixy="4.85378372767622E-07"
        ixz="-6.6236447207852E-09"
        iyy="1.53441439283601E-06"
        iyz="2.43417781458427E-09"
        izz="1.54053017242147E-06" />
    </inertial>
    <visual>
      <origin
        xyz="0 0 0"
        rpy="0 0 0" />
      <geometry>
        <mesh
          filename="package://gcr5g_description/meshes/Link_gripper2.STL" />
      </geometry>
      <material
        name="">
        <color
          rgba="0.752941176470588 0.752941176470588 0.752941176470588 1" />
      </material>
    </visual>
    <collision>
      <origin
        xyz="0 0 0"
        rpy="0 0 0" />
      <geometry>
        <mesh
          filename="package://gcr5g_description/meshes/Link_gripper2.STL" />
      </geometry>
    </collision>
  </link>
  <joint
    name="Joint_gripper2"
    type="revolute">
    <origin
      xyz="0.00738 0.21232 -0.008"
      rpy="0 0 -1.5708" />
    <parent
      link="Link_gripper" />
    <child
      link="Link_gripper2" />
    <axis
      xyz="0 0 1" />
    <limit
      lower="-0.35"
      upper="0.35"
      effort="1"
      velocity="1" />
		<mimic
			joint ="Joint_gripper1"
			multiplier="1"
			offset="0"/>
  </joint>
  <link
    name="Link_gripper3">
    <inertial>
      <origin
        xyz="-0.0129905416241216 -0.00501458682842315 0.00829999776879848"
        rpy="0 0 0" />
      <mass
        value="0.0077013692718047" />
      <inertia
        ixx="8.80119957709077E-07"
        ixy="-9.22317780806695E-07"
        ixz="-5.01751865434528E-13"
        iyy="2.70199630479077E-06"
        iyz="7.32574042822972E-13"
        izz="2.87878325818641E-06" />
    </inertial>
    <visual>
      <origin
        xyz="0 0 0"
        rpy="0 0 0" />
      <geometry>
        <mesh
          filename="package://gcr5g_description/meshes/Link_gripper3.STL" />
      </geometry>
      <material
        name="">
        <color
          rgba="0.752941176470588 0.752941176470588 0.752941176470588 1" />
      </material>
    </visual>
    <collision>
      <origin
        xyz="0 0 0"
        rpy="0 0 0" />
      <geometry>
        <mesh
          filename="package://gcr5g_description/meshes/Link_gripper3.STL" />
      </geometry>
    </collision>
  </link>
  <joint
    name="Joint_gripper3"
    type="revolute">
    <origin
      xyz="-0.0167 0.19555 -0.0083"
      rpy="0 0 -1.5708" />
    <parent
      link="Link_gripper" />
    <child
      link="Link_gripper3" />
    <axis
      xyz="0 0 1" />
    <limit
      lower="-0.35"
      upper="0.35"
      effort="1"
      velocity="1" />
		<mimic
			joint ="Joint_gripper1"
			multiplier="-1"
			offset="0"/>
  </joint>
  <link
    name="Link_gripper3_1">
    <inertial>
      <origin
        xyz="-0.0224887435145321 0.00817428122577157 0.00988520699145941"
        rpy="0 0 0" />
      <mass
        value="0.00588778350213328" />
      <inertia
        ixx="2.50492800230748E-07"
        ixy="3.7069929614721E-07"
        ixz="1.55540068324961E-08"
        iyy="1.50021372793479E-06"
        iyz="-4.14185807442237E-09"
        izz="1.55745564148942E-06" />
    </inertial>
    <visual>
      <origin
        xyz="0 0 0"
        rpy="0 0 0" />
      <geometry>
        <mesh
          filename="package://gcr5g_description/meshes/Link_gripper3_1.STL" />
      </geometry>
      <material
        name="">
        <color
          rgba="0.752941176470588 0.752941176470588 0.752941176470588 1" />
      </material>
    </visual>
    <collision>
      <origin
        xyz="0 0 0"
        rpy="0 0 0" />
      <geometry>
        <mesh
          filename="package://gcr5g_description/meshes/Link_gripper3_1.STL" />
      </geometry>
    </collision>
  </link>
  <joint
    name="Joint_gripper3_1"
    type="revolute">
    <origin
      xyz="-0.05164 -0.01893 -0.0017"
      rpy="0 0 0" />
    <parent
      link="Link_gripper3" />
    <child
      link="Link_gripper3_1" />
    <axis
      xyz="0 0 1" />
    <limit
      lower="-0.35"
      upper="0.35"
      effort="1"
      velocity="1" />
		<mimic
			joint ="Joint_gripper1"
			multiplier="1"
			offset="0"/>
  </joint>
  <link
    name="Link_gripper4">
    <inertial>
      <origin
        xyz="-0.0206898308966732 -0.00756442331308471 0.00808102054231875"
        rpy="0 0 0" />
      <mass
        value="0.00395321330648628" />
      <inertia
        ixx="3.85314556813653E-07"
        ixy="-4.87874899210029E-07"
        ixz="-6.62758616858511E-09"
        iyy="1.53229990943567E-06"
        iyz="-2.42342579795273E-09"
        izz="1.5405301724215E-06" />
    </inertial>
    <visual>
      <origin
        xyz="0 0 0"
        rpy="0 0 0" />
      <geometry>
        <mesh
          filename="package://gcr5g_description/meshes/Link_gripper4.STL" />
      </geometry>
      <material
        name="">
        <color
          rgba="0.752941176470588 0.752941176470588 0.752941176470588 1" />
      </material>
    </visual>
    <collision>
      <origin
        xyz="0 0 0"
        rpy="0 0 0" />
      <geometry>
        <mesh
          filename="package://gcr5g_description/meshes/Link_gripper4.STL" />
      </geometry>
    </collision>
  </link>
  <joint
    name="Joint_gripper4"
    type="revolute">
    <origin
      xyz="-0.00778 0.21232 -0.008"
      rpy="0 0 -1.5708" />
    <parent
      link="Link_gripper" />
    <child
      link="Link_gripper4" />
    <axis
      xyz="0 0 1" />
    <limit
      lower="-0.35"
      upper="0.35"
      effort="1"
      velocity="1" />
		<mimic
			joint ="Joint_gripper1"
			multiplier="-1"
			offset="0"/>
  </joint>
  <link
    name="Link5_1">
    <inertial>
      <origin
        xyz="3.88513615680042E-05 -0.0541490072803046 -0.0768898600766862"
        rpy="0 0 0" />
      <mass
        value="0.0375413118453432" />
      <inertia
        ixx="2.92698896125195E-05"
        ixy="-1.02647745485199E-08"
        ixz="-3.59674349018942E-07"
        iyy="4.08917134960347E-05"
        iyz="3.34967784686783E-06"
        izz="3.01812948967662E-05" />
    </inertial>
    <visual>
      <origin
        xyz="0 0 0"
        rpy="0 0 0" />
      <geometry>
        <mesh
          filename="package://gcr5g_description/meshes/Link5_1.STL" />
      </geometry>
      <material
        name="">
        <color
          rgba="0.352941176470588 0.352941176470588 1 1" />
      </material>
    </visual>
    <collision>
      <origin
        xyz="0 0 0"
        rpy="0 0 0" />
      <geometry>
        <mesh
          filename="package://gcr5g_description/meshes/Link5_1.STL" />
      </geometry>
    </collision>
  </link>
  <joint
    name="Joint5_1"
    type="fixed">
    <origin
      xyz="0 0 0"
      rpy="0 0 0" />
    <parent
      link="Link5" />
    <child
      link="Link5_1" />
    <axis
      xyz="0 0 0" />
  </joint>
  <link
    name="Link4_1">
    <inertial>
      <origin
        xyz="-3.88513552025405E-05 0.0768898600782905 0.0541490072843509"
        rpy="0 0 0" />
      <mass
        value="0.037541311850224" />
      <inertia
        ixx="2.92698896073094E-05"
        ixy="-3.59674351230326E-07"
        ixz="-1.02647768321916E-08"
        iyy="3.01812948963098E-05"
        iyz="3.34967784307818E-06"
        izz="4.08917135003024E-05" />
    </inertial>
    <visual>
      <origin
        xyz="0 0 0"
        rpy="0 0 0" />
      <geometry>
        <mesh
          filename="package://gcr5g_description/meshes/Link4_1.STL" />
      </geometry>
      <material
        name="">
        <color
          rgba="0.352941176470588 0.352941176470588 1 1" />
      </material>
    </visual>
    <collision>
      <origin
        xyz="0 0 0"
        rpy="0 0 0" />
      <geometry>
        <mesh
          filename="package://gcr5g_description/meshes/Link4_1.STL" />
      </geometry>
    </collision>
  </link>
  <joint
    name="Joint4_1"
    type="fixed">
    <origin
      xyz="0 0 0"
      rpy="0 0 0" />
    <parent
      link="Link4" />
    <child
      link="Link4_1" />
    <axis
      xyz="0 0 0" />
  </joint>
  <link
    name="Link3_1">
    <inertial>
      <origin
        xyz="0.395289860067801 -0.173649007279842 3.88513609000662E-05"
        rpy="0 0 0" />
      <mass
        value="0.0375413118311208" />
      <inertia
        ixx="3.01812948940384E-05"
        ixy="-3.34967784246531E-06"
        ixz="3.59674348757157E-07"
        iyy="4.08917134886904E-05"
        iyz="-1.02647753842231E-08"
        izz="2.92698895963743E-05" />
    </inertial>
    <visual>
      <origin
        xyz="0 0 0"
        rpy="0 0 0" />
      <geometry>
        <mesh
          filename="package://gcr5g_description/meshes/Link3_1.STL" />
      </geometry>
      <material
        name="">
        <color
          rgba="0.352941176470588 0.352941176470588 1 1" />
      </material>
    </visual>
    <collision>
      <origin
        xyz="0 0 0"
        rpy="0 0 0" />
      <geometry>
        <mesh
          filename="package://gcr5g_description/meshes/Link3_1.STL" />
      </geometry>
    </collision>
  </link>
  <joint
    name="Joint3_1"
    type="fixed">
    <origin
      xyz="0 0 0"
      rpy="0 0 0" />
    <parent
      link="Link3" />
    <child
      link="Link3_1" />
    <axis
      xyz="0 0 0" />
  </joint>
  <link
    name="Link2_1">
    <inertial>
      <origin
        xyz="0.212552282688768 0.0584481657529934 3.69328456706342E-11"
        rpy="0 0 0" />
      <mass
        value="0.150870904896271" />
      <inertia
        ixx="0.000222581079668353"
        ixy="-1.03060261537401E-12"
        ixz="2.08137401626795E-06"
        iyy="0.00748251815542206"
        iyz="-6.21808990794511E-14"
        izz="0.00734160439358453" />
    </inertial>
    <visual>
      <origin
        xyz="0 0 0"
        rpy="0 0 0" />
      <geometry>
        <mesh
          filename="package://gcr5g_description/meshes/Link2_1.STL" />
      </geometry>
      <material
        name="">
        <color
          rgba="0.352941176470588 0.352941176470588 1 1" />
      </material>
    </visual>
    <collision>
      <origin
        xyz="0 0 0"
        rpy="0 0 0" />
      <geometry>
        <mesh
          filename="package://gcr5g_description/meshes/Link2_1.STL" />
      </geometry>
    </collision>
  </link>
  <joint
    name="Joint2_1"
    type="fixed">
    <origin
      xyz="0 0 0"
      rpy="0 0 0" />
    <parent
      link="Link2" />
    <child
      link="Link2_1" />
    <axis
      xyz="0 0 0" />
  </joint>
  <link
    name="Link1_1">
    <inertial>
      <origin
        xyz="5.93099865830038E-05 -0.00476007097383296 0.0584481657498137"
        rpy="0 0 0" />
      <mass
        value="0.0754354524301621" />
      <inertia
        ixx="0.000108388702205924"
        ixy="6.84132403567906E-08"
        ixz="6.98151300713875E-08"
        iyy="0.00011129027384227"
        iyz="-2.45046345105298E-05"
        izz="0.000178845318157858" />
    </inertial>
    <visual>
      <origin
        xyz="0 0 0"
        rpy="0 0 0" />
      <geometry>
        <mesh
          filename="package://gcr5g_description/meshes/Link1_1.STL" />
      </geometry>
      <material
        name="">
        <color
          rgba="0.352941176470588 0.352941176470588 1 1" />
      </material>
    </visual>
    <collision>
      <origin
        xyz="0 0 0"
        rpy="0 0 0" />
      <geometry>
        <mesh
          filename="package://gcr5g_description/meshes/Link1_1.STL" />
      </geometry>
    </collision>
  </link>
  <joint
    name="Joint1_1"
    type="fixed">
    <origin
      xyz="0 0 0"
      rpy="0 0 0" />
    <parent
      link="Link1" />
    <child
      link="Link1_1" />
    <axis
      xyz="0 0 0" />
  </joint>
</robot>
