<?xml version="1.0" encoding="utf-8"?>
<!-- This URDF was automatically created by SolidWorks to URDF Exporter! Originally created by Stephen Brawner (brawner@gmail.com) 
     Commit Version: 1.5.1-0-g916b5db  Build Version: 1.5.7152.31018
     For more information, please see http://wiki.ros.org/sw_urdf_exporter -->
<robot
  name="gcr3_description">
  <link
    name="base_link">
    <inertial>
      <origin
        xyz="0.000136323162455365 -0.00111434266328092 0.0321200423386677"
        rpy="0 0 0" />
      <mass
        value="0.423388711801464" />
      <inertia
        ixx="0.000841649070117241"
        ixy="1.34840857750186E-06"
        ixz="9.46459604286431E-07"
        iyy="0.000842533429797665"
        iyz="1.10173972502877E-05"
        izz="0.00123577833070647" />
    </inertial>
    <visual>
      <origin
        xyz="0 0 0"
        rpy="0 0 0" />
      <geometry>
        <mesh
          filename="package://gcr3_description/meshes/base_link.STL" />
      </geometry>
      <material
        name="">
        <color
          rgba="0.898039215686275 0.917647058823529 0.929411764705882 1" />
      </material>
    </visual>
    <collision>
      <origin
        xyz="0 0 0"
        rpy="0 0 0" />
      <geometry>
        <mesh
          filename="package://gcr3_description/meshes/base_link.STL" />
      </geometry>
    </collision>
  </link>
  <link
    name="link1">
    <inertial>
      <origin
        xyz="2.20804910209993E-05 0.0043145690792519 0.0613407551209361"
        rpy="0 0 0" />
      <mass
        value="2.40333317338857" />
      <inertia
        ixx="0.00519074780127937"
        ixy="-1.07391073317573E-06"
        ixz="-3.30018632479753E-07"
        iyy="0.00518428813096667"
        iyz="-0.000146087725795125"
        izz="0.00410756603537975" />
    </inertial>
    <visual>
      <origin
        xyz="0 0 0"
        rpy="0 0 0" />
      <geometry>
        <mesh
          filename="package://gcr3_description/meshes/link1.STL" />
      </geometry>
      <material
        name="">
        <color
          rgba="0.792156862745098 0.819607843137255 0.933333333333333 1" />
      </material>
    </visual>
    <collision>
      <origin
        xyz="0 0 0"
        rpy="0 0 0" />
      <geometry>
        <mesh
          filename="package://gcr3_description/meshes/link1.STL" />
      </geometry>
    </collision>
  </link>
  <joint
    name="joint1"
    type="revolute">
    <origin
      xyz="0 0 0.065002"
      rpy="0 0 0" />
    <parent
      link="base_link" />
    <child
      link="link1" />
    <axis
      xyz="0 0 1" />
    <limit
      lower="-3.5"
      upper="3.5"
      effort="1"
      velocity="1" />
  </joint>
  <link
    name="link2">
    <inertial>
      <origin
        xyz="0.106870331992956 0.0630276704911119 2.03496426911948E-05"
        rpy="0 0 0" />
      <mass
        value="4.87303661469465" />
      <inertia
        ixx="0.00883261480812056"
        ixy="-0.00026147712427381"
        ixz="8.14605913731158E-06"
        iyy="0.0670417604325876"
        iyz="-7.86418668519907E-06"
        izz="0.0686400765722775" />
    </inertial>
    <visual>
      <origin
        xyz="0 0 0"
        rpy="0 0 0" />
      <geometry>
        <mesh
          filename="package://gcr3_description/meshes/link2.STL" />
      </geometry>
      <material
        name="">
        <color
          rgba="0.384313725490196 0.384313725490196 0.384313725490196 1" />
      </material>
    </visual>
    <collision>
      <origin
        xyz="0 0 0"
        rpy="0 0 0" />
      <geometry>
        <mesh
          filename="package://gcr3_description/meshes/link2.STL" />
      </geometry>
    </collision>
  </link>
  <joint
    name="joint2"
    type="revolute">
    <origin
      xyz="3.1629E-05 0.047 0.071"
      rpy="0 0 0" />
    <parent
      link="link1" />
    <child
      link="link2" />
    <axis
      xyz="0 1 0" />
    <limit
      lower="-4"
      upper="1"
      effort="1"
      velocity="1" />
  </joint>
  <link
    name="link3">
    <inertial>
      <origin
        xyz="0.16965 -0.045842 -4.8622E-05"
        rpy="0 0 0" />
      <mass
        value="1.9085" />
      <inertia
        ixx="0.0016927"
        ixy="0.00016055"
        ixz="-2.8513E-06"
        iyy="0.011484"
        iyz="1.5355E-06"
        izz="0.011637" />
    </inertial>
    <visual>
      <origin
        xyz="0 0 0"
        rpy="0 0 0" />
      <geometry>
        <mesh
          filename="package://gcr3_description/meshes/link3.STL" />
      </geometry>
      <material
        name="">
        <color
          rgba="0.38431 0.38431 0.38431 1" />
      </material>
    </visual>
    <collision>
      <origin
        xyz="0 0 0"
        rpy="0 0 0" />
      <geometry>
        <mesh
          filename="package://gcr3_description/meshes/link3.STL" />
      </geometry>
    </collision>
  </link>
  <joint
    name="joint3"
    type="revolute">
    <origin
      xyz="0.25 0.01481 3.1629E-05"
      rpy="0 0 0" />
    <parent
      link="link2" />
    <child
      link="link3" />
    <axis
      xyz="0 1 0" />
    <limit
      lower="-3.5"
      upper="3.5"
      effort="1"
      velocity="1" />
  </joint>
  <link
    name="link4">
    <inertial>
      <origin
        xyz="4.23862278264298E-05 0.0427629669530122 -0.00403980637843512"
        rpy="0 0 0" />
      <mass
        value="1.3694590052905" />
      <inertia
        ixx="0.00125065675843402"
        ixy="-6.74032724511125E-07"
        ixz="6.95210386097153E-07"
        iyy="0.00119190461900014"
        iyz="3.32774513339068E-05"
        izz="0.00111384445359654" />
    </inertial>
    <visual>
      <origin
        xyz="0 0 0"
        rpy="0 0 0" />
      <geometry>
        <mesh
          filename="package://gcr3_description/meshes/link4.STL" />
      </geometry>
      <material
        name="">
        <color
          rgba="0.752941176470588 0.752941176470588 0.752941176470588 1" />
      </material>
    </visual>
    <collision>
      <origin
        xyz="0 0 0"
        rpy="0 0 0" />
      <geometry>
        <mesh
          filename="package://gcr3_description/meshes/link4.STL" />
      </geometry>
    </collision>
  </link>
  <joint
    name="joint4"
    type="revolute">
    <origin
      xyz="0.215 -0.00939 0"
      rpy="0 0 0" />
    <parent
      link="link3" />
    <child
      link="link4" />
    <axis
      xyz="0 1 0" />
    <limit
      lower="-4"
      upper="1"
      effort="1"
      velocity="1" />
  </joint>
  <link
    name="link5">
    <inertial>
      <origin
        xyz="-4.25546121172182E-05 0.00387368169245263 -0.0427449520213087"
        rpy="0 0 0" />
      <mass
        value="1.36404290017875" />
      <inertia
        ixx="0.00123857322855258"
        ixy="7.04848990189637E-07"
        ixz="-6.75075642955624E-07"
        iyy="0.00110892240424718"
        iyz="3.22452754661748E-05"
        izz="0.00117993301313163" />
    </inertial>
    <visual>
      <origin
        xyz="0 0 0"
        rpy="0 0 0" />
      <geometry>
        <mesh
          filename="package://gcr3_description/meshes/link5.STL" />
      </geometry>
      <material
        name="">
        <color
          rgba="0.752941176470588 0.752941176470588 0.752941176470588 1" />
      </material>
    </visual>
    <collision>
      <origin
        xyz="0 0 0"
        rpy="0 0 0" />
      <geometry>
        <mesh
          filename="package://gcr3_description/meshes/link5.STL" />
      </geometry>
    </collision>
  </link>
  <joint
    name="joint5"
    type="revolute">
    <origin
      xyz="0 0.0473 -0.04061"
      rpy="0 0 0" />
    <parent
      link="link4" />
    <child
      link="link5" />
    <axis
      xyz="0 0 1" />
    <limit
      lower="-4"
      upper="4"
      effort="1"
      velocity="1" />
  </joint>
  <link
    name="link6">
    <inertial>
      <origin
        xyz="-3.46803696871234E-11 0.0193729037197398 0.000103305759071286"
        rpy="0 0 0" />
      <mass
        value="0.311459167715637" />
      <inertia
        ixx="0.000116649713026086"
        ixy="3.23987019529537E-12"
        ixz="1.56076426230093E-12"
        iyy="0.000159480022583186"
        iyz="-2.91954426444736E-07"
        izz="0.000117223792926036" />
    </inertial>
    <visual>
      <origin
        xyz="0 0 0"
        rpy="0 0 0" />
      <geometry>
        <mesh
          filename="package://gcr3_description/meshes/link6.STL" />
      </geometry>
      <material
        name="">
        <color
          rgba="0.890196078431372 0.890196078431372 0.913725490196078 1" />
      </material>
    </visual>
    <collision>
      <origin
        xyz="0 0 0"
        rpy="0 0 0" />
      <geometry>
        <mesh
          filename="package://gcr3_description/meshes/link6.STL" />
      </geometry>
    </collision>
  </link>
  <joint
    name="joint6"
    type="revolute">
    <origin
      xyz="0 0.04011 -0.0473"
      rpy="0 0 0" />
    <parent
      link="link5" />
    <child
      link="link6" />
    <axis
      xyz="0 1 0" />
    <limit
      lower="-4"
      upper="4"
      effort="1"
      velocity="1" />
  </joint>
</robot>